[2024-06-11T22:20:05.964+0000] {local_task_job_runner.py:120} INFO - ::group::Pre task execution logs
[2024-06-11T22:20:05.986+0000] {taskinstance.py:2076} INFO - Dependencies all met for dep_context=non-requeueable deps ti=<TaskInstance: invoice2receipt.process_each_invoice.delete_temp_file manual__2024-06-11T22:20:00.091534+00:00 map_index=0 [queued]>
[2024-06-11T22:20:05.996+0000] {taskinstance.py:2076} INFO - Dependencies all met for dep_context=requeueable deps ti=<TaskInstance: invoice2receipt.process_each_invoice.delete_temp_file manual__2024-06-11T22:20:00.091534+00:00 map_index=0 [queued]>
[2024-06-11T22:20:05.997+0000] {taskinstance.py:2306} INFO - Starting attempt 1 of 1
[2024-06-11T22:20:06.011+0000] {taskinstance.py:2330} INFO - Executing <Task(_PythonDecoratedOperator): process_each_invoice.delete_temp_file> on 2024-06-11 22:20:00.091534+00:00
[2024-06-11T22:20:06.015+0000] {warnings.py:112} WARNING - /home/***/.local/lib/python3.12/site-packages/***/task/task_runner/standard_task_runner.py:61: DeprecationWarning: This process (pid=1335) is multi-threaded, use of fork() may lead to deadlocks in the child.
  pid = os.fork()

[2024-06-11T22:20:06.017+0000] {standard_task_runner.py:63} INFO - Started process 1337 to run task
[2024-06-11T22:20:06.017+0000] {standard_task_runner.py:90} INFO - Running: ['***', 'tasks', 'run', 'invoice2receipt', 'process_each_invoice.delete_temp_file', 'manual__2024-06-11T22:20:00.091534+00:00', '--job-id', '242', '--raw', '--subdir', 'DAGS_FOLDER/invoice2receipt.py', '--cfg-path', '/tmp/tmp6ebnoass', '--map-index', '0']
[2024-06-11T22:20:06.018+0000] {standard_task_runner.py:91} INFO - Job 242: Subtask process_each_invoice.delete_temp_file
[2024-06-11T22:20:06.059+0000] {task_command.py:426} INFO - Running <TaskInstance: invoice2receipt.process_each_invoice.delete_temp_file manual__2024-06-11T22:20:00.091534+00:00 map_index=0 [running]> on host 678b3b027d57
[2024-06-11T22:20:06.135+0000] {taskinstance.py:2648} INFO - Exporting env vars: AIRFLOW_CTX_DAG_OWNER='Anudeep' AIRFLOW_CTX_DAG_ID='invoice2receipt' AIRFLOW_CTX_TASK_ID='process_each_invoice.delete_temp_file' AIRFLOW_CTX_EXECUTION_DATE='2024-06-11T22:20:00.091534+00:00' AIRFLOW_CTX_TRY_NUMBER='1' AIRFLOW_CTX_DAG_RUN_ID='manual__2024-06-11T22:20:00.091534+00:00'
[2024-06-11T22:20:06.137+0000] {taskinstance.py:430} INFO - ::endgroup::
[2024-06-11T22:20:06.138+0000] {baseoperator.py:400} WARNING - BashOperator.execute cannot be called outside TaskInstance!
[2024-06-11T22:20:06.138+0000] {taskinstance.py:441} INFO - ::group::Post task execution logs
[2024-06-11T22:20:06.139+0000] {taskinstance.py:2905} ERROR - Task failed with exception
Traceback (most recent call last):
  File "/home/airflow/.local/lib/python3.12/site-packages/airflow/models/taskinstance.py", line 465, in _execute_task
    result = _execute_callable(context=context, **execute_callable_kwargs)
             ^^^^^^^^^^^^^^^^^^^^^^^^^^^^^^^^^^^^^^^^^^^^^^^^^^^^^^^^^^^^^
  File "/home/airflow/.local/lib/python3.12/site-packages/airflow/models/taskinstance.py", line 432, in _execute_callable
    return execute_callable(context=context, **execute_callable_kwargs)
           ^^^^^^^^^^^^^^^^^^^^^^^^^^^^^^^^^^^^^^^^^^^^^^^^^^^^^^^^^^^^
  File "/home/airflow/.local/lib/python3.12/site-packages/airflow/models/baseoperator.py", line 401, in wrapper
    return func(self, *args, **kwargs)
           ^^^^^^^^^^^^^^^^^^^^^^^^^^^
  File "/home/airflow/.local/lib/python3.12/site-packages/airflow/decorators/base.py", line 265, in execute
    return_value = super().execute(context)
                   ^^^^^^^^^^^^^^^^^^^^^^^^
  File "/home/airflow/.local/lib/python3.12/site-packages/airflow/models/baseoperator.py", line 401, in wrapper
    return func(self, *args, **kwargs)
           ^^^^^^^^^^^^^^^^^^^^^^^^^^^
  File "/home/airflow/.local/lib/python3.12/site-packages/airflow/operators/python.py", line 235, in execute
    return_value = self.execute_callable()
                   ^^^^^^^^^^^^^^^^^^^^^^^
  File "/home/airflow/.local/lib/python3.12/site-packages/airflow/operators/python.py", line 252, in execute_callable
    return self.python_callable(*self.op_args, **self.op_kwargs)
           ^^^^^^^^^^^^^^^^^^^^^^^^^^^^^^^^^^^^^^^^^^^^^^^^^^^^^
  File "/opt/airflow/dags/invoice2receipt.py", line 45, in delete_temp_file
    delete_file.execute(context=None)
  File "/home/airflow/.local/lib/python3.12/site-packages/airflow/models/baseoperator.py", line 401, in wrapper
    return func(self, *args, **kwargs)
           ^^^^^^^^^^^^^^^^^^^^^^^^^^^
  File "/home/airflow/.local/lib/python3.12/site-packages/airflow/operators/bash.py", line 223, in execute
    env = self.get_env(context)
          ^^^^^^^^^^^^^^^^^^^^^
  File "/home/airflow/.local/lib/python3.12/site-packages/airflow/operators/bash.py", line 208, in get_env
    airflow_context_vars = context_to_airflow_vars(context, in_env_var_format=True)
                           ^^^^^^^^^^^^^^^^^^^^^^^^^^^^^^^^^^^^^^^^^^^^^^^^^^^^^^^^
  File "/home/airflow/.local/lib/python3.12/site-packages/airflow/utils/operator_helpers.py", line 82, in context_to_airflow_vars
    task = context.get("task")
           ^^^^^^^^^^^
AttributeError: 'NoneType' object has no attribute 'get'
[2024-06-11T22:20:06.154+0000] {taskinstance.py:1206} INFO - Marking task as FAILED. dag_id=invoice2receipt, task_id=process_each_invoice.delete_temp_file, run_id=manual__2024-06-11T22:20:00.091534+00:00, map_index=0, execution_date=20240611T222000, start_date=20240611T222005, end_date=20240611T222006
[2024-06-11T22:20:06.166+0000] {standard_task_runner.py:110} ERROR - Failed to execute job 242 for task process_each_invoice.delete_temp_file ('NoneType' object has no attribute 'get'; 1337)
[2024-06-11T22:20:06.190+0000] {local_task_job_runner.py:240} INFO - Task exited with return code 1
[2024-06-11T22:20:06.216+0000] {local_task_job_runner.py:222} INFO - ::endgroup::
