[2024-06-12T06:37:39.463+0000] {local_task_job_runner.py:120} INFO - ::group::Pre task execution logs
[2024-06-12T06:37:39.486+0000] {taskinstance.py:2076} INFO - Dependencies all met for dep_context=non-requeueable deps ti=<TaskInstance: invoice2receipt.write_data_to_S3 manual__2024-06-12T06:36:29.520787+00:00 [queued]>
[2024-06-12T06:37:39.500+0000] {taskinstance.py:2076} INFO - Dependencies all met for dep_context=requeueable deps ti=<TaskInstance: invoice2receipt.write_data_to_S3 manual__2024-06-12T06:36:29.520787+00:00 [queued]>
[2024-06-12T06:37:39.502+0000] {taskinstance.py:2306} INFO - Starting attempt 1 of 1
[2024-06-12T06:37:39.518+0000] {taskinstance.py:2330} INFO - Executing <Task(_PythonDecoratedOperator): write_data_to_S3> on 2024-06-12 06:36:29.520787+00:00
[2024-06-12T06:37:39.526+0000] {warnings.py:112} WARNING - /home/***/.local/lib/python3.12/site-packages/***/task/task_runner/standard_task_runner.py:61: DeprecationWarning: This process (pid=298) is multi-threaded, use of fork() may lead to deadlocks in the child.
  pid = os.fork()

[2024-06-12T06:37:39.528+0000] {standard_task_runner.py:63} INFO - Started process 299 to run task
[2024-06-12T06:37:39.528+0000] {standard_task_runner.py:90} INFO - Running: ['***', 'tasks', 'run', 'invoice2receipt', 'write_data_to_S3', 'manual__2024-06-12T06:36:29.520787+00:00', '--job-id', '400', '--raw', '--subdir', 'DAGS_FOLDER/invoice2receipt.py', '--cfg-path', '/tmp/tmpiudtdd10']
[2024-06-12T06:37:39.529+0000] {standard_task_runner.py:91} INFO - Job 400: Subtask write_data_to_S3
[2024-06-12T06:37:39.580+0000] {task_command.py:426} INFO - Running <TaskInstance: invoice2receipt.write_data_to_S3 manual__2024-06-12T06:36:29.520787+00:00 [running]> on host 678b3b027d57
[2024-06-12T06:37:39.706+0000] {taskinstance.py:2648} INFO - Exporting env vars: AIRFLOW_CTX_DAG_OWNER='Anudeep' AIRFLOW_CTX_DAG_ID='invoice2receipt' AIRFLOW_CTX_TASK_ID='write_data_to_S3' AIRFLOW_CTX_EXECUTION_DATE='2024-06-12T06:36:29.520787+00:00' AIRFLOW_CTX_TRY_NUMBER='1' AIRFLOW_CTX_DAG_RUN_ID='manual__2024-06-12T06:36:29.520787+00:00'
[2024-06-12T06:37:39.709+0000] {taskinstance.py:430} INFO - ::endgroup::
[2024-06-12T06:37:39.713+0000] {taskinstance.py:441} INFO - ::group::Post task execution logs
[2024-06-12T06:37:39.714+0000] {taskinstance.py:2905} ERROR - Task failed with exception
Traceback (most recent call last):
  File "/home/airflow/.local/lib/python3.12/site-packages/airflow/models/taskinstance.py", line 465, in _execute_task
    result = _execute_callable(context=context, **execute_callable_kwargs)
             ^^^^^^^^^^^^^^^^^^^^^^^^^^^^^^^^^^^^^^^^^^^^^^^^^^^^^^^^^^^^^
  File "/home/airflow/.local/lib/python3.12/site-packages/airflow/models/taskinstance.py", line 432, in _execute_callable
    return execute_callable(context=context, **execute_callable_kwargs)
           ^^^^^^^^^^^^^^^^^^^^^^^^^^^^^^^^^^^^^^^^^^^^^^^^^^^^^^^^^^^^
  File "/home/airflow/.local/lib/python3.12/site-packages/airflow/models/baseoperator.py", line 401, in wrapper
    return func(self, *args, **kwargs)
           ^^^^^^^^^^^^^^^^^^^^^^^^^^^
  File "/home/airflow/.local/lib/python3.12/site-packages/airflow/decorators/base.py", line 265, in execute
    return_value = super().execute(context)
                   ^^^^^^^^^^^^^^^^^^^^^^^^
  File "/home/airflow/.local/lib/python3.12/site-packages/airflow/models/baseoperator.py", line 401, in wrapper
    return func(self, *args, **kwargs)
           ^^^^^^^^^^^^^^^^^^^^^^^^^^^
  File "/home/airflow/.local/lib/python3.12/site-packages/airflow/operators/python.py", line 235, in execute
    return_value = self.execute_callable()
                   ^^^^^^^^^^^^^^^^^^^^^^^
  File "/home/airflow/.local/lib/python3.12/site-packages/airflow/operators/python.py", line 252, in execute_callable
    return self.python_callable(*self.op_args, **self.op_kwargs)
           ^^^^^^^^^^^^^^^^^^^^^^^^^^^^^^^^^^^^^^^^^^^^^^^^^^^^^
  File "/opt/airflow/dags/invoice2receipt.py", line 95, in write_data_to_S3
    data = json.dumps(data)
           ^^^^^^^^^^^^^^^^
  File "/usr/local/lib/python3.12/json/__init__.py", line 231, in dumps
    return _default_encoder.encode(obj)
           ^^^^^^^^^^^^^^^^^^^^^^^^^^^^
  File "/usr/local/lib/python3.12/json/encoder.py", line 200, in encode
    chunks = self.iterencode(o, _one_shot=True)
             ^^^^^^^^^^^^^^^^^^^^^^^^^^^^^^^^^^
  File "/usr/local/lib/python3.12/json/encoder.py", line 258, in iterencode
    return _iterencode(o, 0)
           ^^^^^^^^^^^^^^^^^
  File "/usr/local/lib/python3.12/json/encoder.py", line 180, in default
    raise TypeError(f'Object of type {o.__class__.__name__} '
TypeError: Object of type LazyXComAccess is not JSON serializable
[2024-06-12T06:37:39.741+0000] {taskinstance.py:1206} INFO - Marking task as FAILED. dag_id=invoice2receipt, task_id=write_data_to_S3, run_id=manual__2024-06-12T06:36:29.520787+00:00, execution_date=20240612T063629, start_date=20240612T063739, end_date=20240612T063739
[2024-06-12T06:37:39.764+0000] {standard_task_runner.py:110} ERROR - Failed to execute job 400 for task write_data_to_S3 (Object of type LazyXComAccess is not JSON serializable; 299)
[2024-06-12T06:37:39.783+0000] {local_task_job_runner.py:240} INFO - Task exited with return code 1
[2024-06-12T06:37:39.810+0000] {taskinstance.py:3503} INFO - 0 downstream tasks scheduled from follow-on schedule check
[2024-06-12T06:37:39.815+0000] {local_task_job_runner.py:222} INFO - ::endgroup::
