[2024-06-11T05:25:27.550+0000] {local_task_job_runner.py:120} INFO - ::group::Pre task execution logs
[2024-06-11T05:25:27.569+0000] {taskinstance.py:2076} INFO - Dependencies all met for dep_context=non-requeueable deps ti=<TaskInstance: hello_word.read_files_from_path manual__2024-06-11T05:25:26.619667+00:00 [queued]>
[2024-06-11T05:25:27.576+0000] {taskinstance.py:2076} INFO - Dependencies all met for dep_context=requeueable deps ti=<TaskInstance: hello_word.read_files_from_path manual__2024-06-11T05:25:26.619667+00:00 [queued]>
[2024-06-11T05:25:27.578+0000] {taskinstance.py:2306} INFO - Starting attempt 1 of 1
[2024-06-11T05:25:27.592+0000] {taskinstance.py:2330} INFO - Executing <Task(PythonOperator): read_files_from_path> on 2024-06-11 05:25:26.619667+00:00
[2024-06-11T05:25:27.598+0000] {warnings.py:112} WARNING - /home/***/.local/lib/python3.12/site-packages/***/task/task_runner/standard_task_runner.py:61: DeprecationWarning: This process (pid=1770) is multi-threaded, use of fork() may lead to deadlocks in the child.
  pid = os.fork()

[2024-06-11T05:25:27.600+0000] {standard_task_runner.py:63} INFO - Started process 1771 to run task
[2024-06-11T05:25:27.599+0000] {standard_task_runner.py:90} INFO - Running: ['***', 'tasks', 'run', 'hello_word', 'read_files_from_path', 'manual__2024-06-11T05:25:26.619667+00:00', '--job-id', '94', '--raw', '--subdir', 'DAGS_FOLDER/simple_hello_world.py', '--cfg-path', '/tmp/tmpjl2ou7gn']
[2024-06-11T05:25:27.601+0000] {standard_task_runner.py:91} INFO - Job 94: Subtask read_files_from_path
[2024-06-11T05:25:27.680+0000] {task_command.py:426} INFO - Running <TaskInstance: hello_word.read_files_from_path manual__2024-06-11T05:25:26.619667+00:00 [running]> on host 678b3b027d57
[2024-06-11T05:25:27.754+0000] {taskinstance.py:2648} INFO - Exporting env vars: AIRFLOW_CTX_DAG_OWNER='Anudeep' AIRFLOW_CTX_DAG_ID='hello_word' AIRFLOW_CTX_TASK_ID='read_files_from_path' AIRFLOW_CTX_EXECUTION_DATE='2024-06-11T05:25:26.619667+00:00' AIRFLOW_CTX_TRY_NUMBER='1' AIRFLOW_CTX_DAG_RUN_ID='manual__2024-06-11T05:25:26.619667+00:00'
[2024-06-11T05:25:27.755+0000] {taskinstance.py:430} INFO - ::endgroup::
[2024-06-11T05:25:27.771+0000] {base.py:84} INFO - Using connection ID 'invoices' for task execution.
[2024-06-11T05:25:27.921+0000] {python.py:237} INFO - Done. Returned value was: ['/opt/***/dags/invoices/sample1.json', '/opt/***/dags/invoices/sample2.json']
[2024-06-11T05:25:27.929+0000] {taskinstance.py:441} INFO - ::group::Post task execution logs
[2024-06-11T05:25:27.940+0000] {taskinstance.py:2905} ERROR - Task failed with exception
Traceback (most recent call last):
  File "/home/airflow/.local/lib/python3.12/site-packages/airflow/models/taskinstance.py", line 474, in _execute_task
    raise AirflowException(
airflow.exceptions.AirflowException: Returned output was type <class 'list'> expected dictionary for multiple_outputs
[2024-06-11T05:25:27.952+0000] {taskinstance.py:1206} INFO - Marking task as FAILED. dag_id=hello_word, task_id=read_files_from_path, run_id=manual__2024-06-11T05:25:26.619667+00:00, execution_date=20240611T052526, start_date=20240611T052527, end_date=20240611T052527
[2024-06-11T05:25:27.967+0000] {standard_task_runner.py:110} ERROR - Failed to execute job 94 for task read_files_from_path (Returned output was type <class 'list'> expected dictionary for multiple_outputs; 1771)
[2024-06-11T05:25:27.976+0000] {local_task_job_runner.py:240} INFO - Task exited with return code 1
[2024-06-11T05:25:27.998+0000] {taskinstance.py:3503} INFO - 0 downstream tasks scheduled from follow-on schedule check
[2024-06-11T05:25:28.027+0000] {local_task_job_runner.py:222} INFO - ::endgroup::
