[2024-06-11T04:21:56.277+0000] {local_task_job_runner.py:120} INFO - ::group::Pre task execution logs
[2024-06-11T04:21:56.296+0000] {taskinstance.py:2076} INFO - Dependencies all met for dep_context=non-requeueable deps ti=<TaskInstance: hello_world.create_file_processing_tasks manual__2024-06-11T04:21:53.461616+00:00 [queued]>
[2024-06-11T04:21:56.304+0000] {taskinstance.py:2076} INFO - Dependencies all met for dep_context=requeueable deps ti=<TaskInstance: hello_world.create_file_processing_tasks manual__2024-06-11T04:21:53.461616+00:00 [queued]>
[2024-06-11T04:21:56.306+0000] {taskinstance.py:2306} INFO - Starting attempt 1 of 1
[2024-06-11T04:21:56.319+0000] {taskinstance.py:2330} INFO - Executing <Task(PythonOperator): create_file_processing_tasks> on 2024-06-11 04:21:53.461616+00:00
[2024-06-11T04:21:56.326+0000] {warnings.py:112} WARNING - /home/***/.local/lib/python3.12/site-packages/***/task/task_runner/standard_task_runner.py:61: DeprecationWarning: This process (pid=1241) is multi-threaded, use of fork() may lead to deadlocks in the child.
  pid = os.fork()

[2024-06-11T04:21:56.328+0000] {standard_task_runner.py:63} INFO - Started process 1242 to run task
[2024-06-11T04:21:56.328+0000] {standard_task_runner.py:90} INFO - Running: ['***', 'tasks', 'run', 'hello_world', 'create_file_processing_tasks', 'manual__2024-06-11T04:21:53.461616+00:00', '--job-id', '81', '--raw', '--subdir', 'DAGS_FOLDER/simple_hello_world.py', '--cfg-path', '/tmp/tmp7ujt_819']
[2024-06-11T04:21:56.329+0000] {standard_task_runner.py:91} INFO - Job 81: Subtask create_file_processing_tasks
[2024-06-11T04:21:56.452+0000] {task_command.py:426} INFO - Running <TaskInstance: hello_world.create_file_processing_tasks manual__2024-06-11T04:21:53.461616+00:00 [running]> on host 678b3b027d57
[2024-06-11T04:21:56.514+0000] {taskinstance.py:2648} INFO - Exporting env vars: AIRFLOW_CTX_DAG_OWNER='Anudeep' AIRFLOW_CTX_DAG_ID='hello_world' AIRFLOW_CTX_TASK_ID='create_file_processing_tasks' AIRFLOW_CTX_EXECUTION_DATE='2024-06-11T04:21:53.461616+00:00' AIRFLOW_CTX_TRY_NUMBER='1' AIRFLOW_CTX_DAG_RUN_ID='manual__2024-06-11T04:21:53.461616+00:00'
[2024-06-11T04:21:56.515+0000] {taskinstance.py:430} INFO - ::endgroup::
[2024-06-11T04:21:56.535+0000] {taskinstance.py:441} INFO - ::group::Post task execution logs
[2024-06-11T04:21:56.542+0000] {taskinstance.py:2905} ERROR - Task failed with exception
Traceback (most recent call last):
  File "/home/airflow/.local/lib/python3.12/site-packages/airflow/models/taskinstance.py", line 465, in _execute_task
    result = _execute_callable(context=context, **execute_callable_kwargs)
             ^^^^^^^^^^^^^^^^^^^^^^^^^^^^^^^^^^^^^^^^^^^^^^^^^^^^^^^^^^^^^
  File "/home/airflow/.local/lib/python3.12/site-packages/airflow/models/taskinstance.py", line 432, in _execute_callable
    return execute_callable(context=context, **execute_callable_kwargs)
           ^^^^^^^^^^^^^^^^^^^^^^^^^^^^^^^^^^^^^^^^^^^^^^^^^^^^^^^^^^^^
  File "/home/airflow/.local/lib/python3.12/site-packages/airflow/models/baseoperator.py", line 401, in wrapper
    return func(self, *args, **kwargs)
           ^^^^^^^^^^^^^^^^^^^^^^^^^^^
  File "/home/airflow/.local/lib/python3.12/site-packages/airflow/operators/python.py", line 235, in execute
    return_value = self.execute_callable()
                   ^^^^^^^^^^^^^^^^^^^^^^^
  File "/home/airflow/.local/lib/python3.12/site-packages/airflow/operators/python.py", line 252, in execute_callable
    return self.python_callable(*self.op_args, **self.op_kwargs)
           ^^^^^^^^^^^^^^^^^^^^^^^^^^^^^^^^^^^^^^^^^^^^^^^^^^^^^
  File "/opt/airflow/dags/simple_hello_world.py", line 50, in create_file_processing_tasks
    with TaskGroup("file_processing_tasks", tooltip="Process files in parallel") as group:
         ^^^^^^^^^^^^^^^^^^^^^^^^^^^^^^^^^^^^^^^^^^^^^^^^^^^^^^^^^^^^^^^^^^^^^^^
  File "/home/airflow/.local/lib/python3.12/site-packages/airflow/utils/task_group.py", line 124, in __init__
    raise AirflowException("TaskGroup can only be used inside a dag")
airflow.exceptions.AirflowException: TaskGroup can only be used inside a dag
[2024-06-11T04:21:56.548+0000] {taskinstance.py:1206} INFO - Marking task as FAILED. dag_id=hello_world, task_id=create_file_processing_tasks, run_id=manual__2024-06-11T04:21:53.461616+00:00, execution_date=20240611T042153, start_date=20240611T042156, end_date=20240611T042156
[2024-06-11T04:21:56.559+0000] {standard_task_runner.py:110} ERROR - Failed to execute job 81 for task create_file_processing_tasks (TaskGroup can only be used inside a dag; 1242)
[2024-06-11T04:21:56.583+0000] {local_task_job_runner.py:240} INFO - Task exited with return code 1
[2024-06-11T04:21:56.602+0000] {taskinstance.py:3503} INFO - 0 downstream tasks scheduled from follow-on schedule check
[2024-06-11T04:21:56.659+0000] {local_task_job_runner.py:222} INFO - ::endgroup::
